[[03/24/2019 12:09:28 PM]] Internal Server Error: /livetext/
Traceback (most recent call last):
  File "/home/hina/Music/Django/AnalogPen/venv/lib/python3.4/site-packages/django/core/handlers/exception.py", line 35, in inner
    response = get_response(request)
  File "/home/hina/Music/Django/AnalogPen/venv/lib/python3.4/site-packages/django/core/handlers/base.py", line 128, in _get_response
    response = self.process_exception_by_middleware(e, request)
  File "/home/hina/Music/Django/AnalogPen/venv/lib/python3.4/site-packages/django/core/handlers/base.py", line 126, in _get_response
    response = wrapped_callback(request, *callback_args, **callback_kwargs)
  File "/home/hina/Music/Django/AnalogPen/home/views.py", line 16, in live_text
    demo.generate(text)
  File "/home/hina/Music/Django/handwriting-synthesis/demo.py", line 153, in generate
    hand = Hand()
  File "/home/hina/Music/Django/handwriting-synthesis/demo.py", line 39, in __init__
    self.nn.restore()
  File "/home/hina/Music/Django/handwriting-synthesis/tf_base_model.py", line 326, in restore
    saver.restore(self.session, model_path)
  File "/home/hina/Music/Django/AnalogPen/venv/lib/python3.4/site-packages/tensorflow/python/training/saver.py", line 1751, in restore
    raise ValueError("Can't load save_path when it is None.")
ValueError: Can't load save_path when it is None.
